<?xml version="1.0" ?>
<!-- =================================================================================== -->
<!-- |    This document was autogenerated by xacro from robot.urdf.xacro               | -->
<!-- |    EDITING THIS FILE BY HAND IS NOT RECOMMENDED                                 | -->
<!-- =================================================================================== -->
<robot name="auto_robot">
  <link name="base_link">
    <inertial>
      <origin rpy="0 0 0" xyz="-0.00177767886836495 -7.08145711406941E-05 0.0345244109350669"/>
      <mass value="0.749591825708612"/>
      <inertia ixx="0.00560242940522896" ixy="-3.10886247756778E-06" ixz="7.02379711896478E-05" iyy="0.00543989398233584" iyz="-2.42126647279533E-17" izz="0.00951025265754031"/>
    </inertial>
    <visual>
      <origin rpy="0 0 0" xyz="0 0 0"/>
      <geometry>
        <mesh filename="package://auto_robot/meshes/base_link.STL"/>
      </geometry>
      <material name="body_color">
        <color rgba="0.792 0.819 0.933 1"/>
      </material>
    </visual>
    <collision>
      <origin rpy="0 0 0" xyz="0 0 0.05"/>
      <geometry>
        <cylinder length="0.10" radius="0.13"/>
      </geometry>
    </collision>
  </link>
  <link name="wheel_1">
    <inertial>
      <origin rpy="0 0 0" xyz="1.0863E-06 -2.2552E-06 0.0075339"/>
      <mass value="0.039266"/>
      <inertia ixx="3.5298E-06" ixy="1.754E-10" ixz="1.4711E-10" iyy="3.5298E-06" iyz="-1.6617E-10" izz="5.3943E-06"/>
    </inertial>
    <visual>
      <origin rpy="0 0 0" xyz="0 0 0"/>
      <geometry>
        <mesh filename="package://auto_robot/meshes/wheel_1.STL"/>
      </geometry>
      <material name="wheel_color">
        <color rgba="0.1 0.1 0.1 1"/>
      </material>
    </visual>
    <collision>
      <origin rpy="0 0 0" xyz="0 0 0"/>
      <geometry>
        <cylinder length="0.03" radius="0.0325"/>
      </geometry>
    </collision>
  </link>
  <joint name="joint_1" type="continuous">
    <origin rpy="1.5708 0 1.5708" xyz="0.12368 -0.00013859 -0.019"/>
    <parent link="base_link"/>
    <child link="wheel_1"/>
    <axis xyz="0 0 1"/>
  </joint>
  <link name="wheel_2">
    <inertial>
      <origin rpy="0 0 0" xyz="1.0862E-06 -2.255E-06 0.0075339"/>
      <mass value="0.039266"/>
      <inertia ixx="3.5297E-06" ixy="3.9609E-11" ixz="1.471E-10" iyy="3.5297E-06" iyz="-1.6617E-10" izz="5.3942E-06"/>
    </inertial>
    <visual>
      <origin rpy="0 0 0" xyz="0 0 0"/>
      <geometry>
        <mesh filename="package://auto_robot/meshes/wheel_2.STL"/>
      </geometry>
      <material name="wheel_color">
        <color rgba="0.1 0.1 0.1 1"/>
      </material>
    </visual>
    <collision>
      <origin rpy="0 0 0" xyz="0 0 0"/>
      <geometry>
        <cylinder length="0.03" radius="0.0325"/>
      </geometry>
    </collision>
  </link>
  <joint name="joint_2" type="continuous">
    <origin rpy="1.5708 0 -2.618" xyz="-0.062025 0.10707 -0.019"/>
    <parent link="base_link"/>
    <child link="wheel_2"/>
    <axis xyz="0 0 1"/>
  </joint>
  <link name="wheel_3">
    <inertial>
      <origin rpy="0 0 0" xyz="1.0862E-06 -2.2551E-06 0.0075339"/>
      <mass value="0.039266"/>
      <inertia ixx="3.5297E-06" ixy="6.0263E-11" ixz="1.471E-10" iyy="3.5296E-06" iyz="-1.6618E-10" izz="5.3941E-06"/>
    </inertial>
    <visual>
      <origin rpy="0 0 0" xyz="0 0 0"/>
      <geometry>
        <mesh filename="package://auto_robot/meshes/wheel_3.STL"/>
      </geometry>
      <material name="wheel_color">
        <color rgba="0.1 0.1 0.1 1"/>
      </material>
    </visual>
    <collision>
      <origin rpy="0 0 0" xyz="0 0 0"/>
      <geometry>
        <cylinder length="0.03" radius="0.0325"/>
      </geometry>
    </collision>
  </link>
  <joint name="joint_3" type="continuous">
    <origin rpy="1.5708 0 -0.5236" xyz="-0.062024 -0.10735 -0.019"/>
    <parent link="base_link"/>
    <child link="wheel_3"/>
    <axis xyz="0 0 1"/>
  </joint>
  <link name="robot_footprint"/>
  <joint name="dummy_joint" type="fixed">
    <parent link="robot_footprint"/>
    <child link="base_link"/>
    <origin rpy="0 0 0" xyz="0 0 0.0515"/>
  </joint>
  <link name="lidar">
    <inertial>
      <origin rpy="0 0 0" xyz="0.0067682 -0.00020713 -0.022521"/>
      <mass value="0.17118"/>
      <inertia ixx="7.9535E-05" ixy="-1.035E-07" ixz="2.0281E-05" iyy="0.00012426" iyz="-3.9476E-07" izz="0.00014191"/>
    </inertial>
    <visual>
      <origin rpy="0 0 0" xyz="0 0 0"/>
      <geometry>
        <mesh filename="package://auto_robot/meshes/lidar.STL"/>
      </geometry>
      <material name="lidar_color">
        <color rgba="0.79216 0.81961 0.93333 1"/>
      </material>
    </visual>
    <collision>
      <origin rpy="0 0 0" xyz="0 0 0"/>
      <geometry>
        <mesh filename="package://auto_robot/meshes/lidar.STL"/>
      </geometry>
    </collision>
  </link>
  <joint name="lidar_joint" type="fixed">
    <origin rpy="0 0 0" xyz="-0.00012313 -2.5346E-05 0.1797"/>
    <parent link="base_link"/>
    <child link="lidar"/>
    <axis xyz="0 0 0"/>
  </joint>
  <link name="oak_camera">
    <inertial>
      <origin rpy="0 0 0" xyz="-0.0086 -5.8579E-18 0"/>
      <mass value="0.041718"/>
      <inertia ixx="3.0322E-05" ixy="-8.0273E-23" ixz="-4.5515E-23" iyy="3.5543E-06" iyz="-4.7563E-21" izz="2.8825E-05"/>
    </inertial>
    <visual>
      <origin rpy="0 0 0" xyz="0 0 0"/>
      <geometry>
        <mesh filename="package://auto_robot/meshes/oak_camera.STL"/>
      </geometry>
      <material name="camera_color">
        <color rgba="0.25098 0.25098 0.25098 1"/>
      </material>
    </visual>
    <collision>
      <origin rpy="0 0 0" xyz="0 0 0"/>
      <geometry>
        <mesh filename="package://auto_robot/meshes/oak_camera.STL"/>
      </geometry>
    </collision>
  </link>
  <joint name="oak_joint" type="fixed">
    <origin rpy="0 0 0" xyz="0.12008 -0.00013908 0.12046"/>
    <parent link="base_link"/>
    <child link="oak_camera"/>
    <axis xyz="0 0 0"/>
  </joint>
  <link name="camera_link"/>
  <joint name="camera_link_joint" type="fixed">
    <parent link="oak_camera"/>
    <child link="camera_link"/>
    <origin rpy="0 0 0" xyz="0 0 0"/>
  </joint>
  <link name="camera_link_optical"/>
  <joint name="camera_optical_joint" type="fixed">
    <parent link="camera_link"/>
    <child link="camera_link_optical"/>
    <origin rpy="-1.5707963267948966 0 -1.5707963267948966" xyz="0 0 0"/>
  </joint>
  <link name="imu_link">
    <visual>
      <geometry>
        <box size="0.0001 0.0001 0.0001"/>
      </geometry>
      <material name="imu_color">
        <color rgba="1.0 0.0 0.0 1"/>
      </material>
    </visual>
    <collision>
      <geometry>
        <box size="0.0001 0.0001 0.0001"/>
      </geometry>
    </collision>
    <inertial>
      <mass value="0.01"/>
      <inertia ixx="0.0001" ixy="0" ixz="0" iyy="0.0001" iyz="0" izz="0.0001"/>
    </inertial>
  </link>
  <joint name="imu_joint" type="fixed">
    <parent link="base_link"/>
    <child link="imu_link"/>
    <origin rpy="0 0 0" xyz="0 0 0"/>
  </joint>
  <ros2_control name="GazeboSystem" type="system">
    <hardware>
      <plugin>gazebo_ros2_control/GazeboSystem</plugin>
    </hardware>
    <joint name="joint_1">
      <command_interface name="velocity"/>
      <state_interface name="velocity"/>
      <state_interface name="position"/>
    </joint>
    <joint name="joint_2">
      <command_interface name="velocity"/>
      <state_interface name="velocity"/>
      <state_interface name="position"/>
    </joint>
    <joint name="joint_3">
      <command_interface name="velocity"/>
      <state_interface name="velocity"/>
      <state_interface name="position"/>
    </joint>
  </ros2_control>
  <gazebo>
    <plugin filename="libgazebo_ros2_control.so" name="gazebo_ros2_control">
      <parameters>/home/gharably/ausrabot_ws/install/auto_robot/share/auto_robot/config/robot_controller.yaml</parameters>
      <robot_param>robot_description</robot_param>
      <robot_param_node>robot_state_publisher</robot_param_node>
    </plugin>
  </gazebo>
  <gazebo reference="base_link">
    <material>Gazebo/White</material>
    <mu1>0.2</mu1>
    <mu2>0.2</mu2>
  </gazebo>
  <gazebo reference="wheel_1">
    <material>Gazebo/DarkGrey</material>
    <mu1>1.0</mu1>
    <mu2>0.001</mu2>
    <fdir1>1 0 0</fdir1>
    <kp>1000000.0</kp>
    <kd>100.0</kd>
    <minDepth>0.001</minDepth>
  </gazebo>
  <gazebo reference="wheel_2">
    <material>Gazebo/DarkGrey</material>
    <mu1>1.0</mu1>
    <mu2>0.001</mu2>
    <fdir1>1 0 0</fdir1>
    <kp>1000000.0</kp>
    <kd>100.0</kd>
    <minDepth>0.001</minDepth>
  </gazebo>
  <gazebo reference="wheel_3">
    <material>Gazebo/DarkGrey</material>
    <mu1>1.0</mu1>
    <mu2>0.001</mu2>
    <fdir1>1 0 0</fdir1>
    <kp>1000000.0</kp>
    <kd>100.0</kd>
    <minDepth>0.001</minDepth>
  </gazebo>
  <gazebo reference="lidar">
    <material>Gazebo/White</material>
  </gazebo>
  <gazebo reference="oak_camera">
    <material>Gazebo/DarkGrey</material>
  </gazebo>
  <gazebo reference="lidar">
    <sensor name="rplidar_a1" type="ray">
      <pose>0 0 0 0 0 0</pose>
      <always_on>true</always_on>
      <visualize>true</visualize>
      <update_rate>5.5</update_rate>
      <ray>
        <scan>
          <horizontal>
            <samples>360</samples>
            <resolution>1</resolution>
            <min_angle>-3.14159265</min_angle>
            <max_angle>3.14159265</max_angle>
          </horizontal>
        </scan>
        <range>
          <min>0.15</min>
          <max>12.0</max>
          <resolution>0.01</resolution>
        </range>
        <noise>
          <type>gaussian</type>
          <mean>0.0</mean>
          <stddev>0.01</stddev>
        </noise>
      </ray>
      <plugin filename="libgazebo_ros_ray_sensor.so" name="gazebo_ros_lidar">
        <ros>
          <remapping>~/out:=scan</remapping>
        </ros>
        <output_type>sensor_msgs/LaserScan</output_type>
        <frame_name>lidar</frame_name>
      </plugin>
    </sensor>
  </gazebo>
  <gazebo reference="imu_link">
    <sensor name="imu_sensor" type="imu">
      <always_on>true</always_on>
      <update_rate>100</update_rate>
      <visualize>true</visualize>
      <plugin filename="libgazebo_ros_imu_sensor.so" name="gazebo_ros_imu">
        <ros>
          <remapping>~/out:=imu</remapping>
        </ros>
        <frame_name>imu_link</frame_name>
        <initial_orientation_as_reference>false</initial_orientation_as_reference>
      </plugin>
      <imu>
        <angular_velocity>
          <x>
            <noise type="gaussian">
              <mean>0.0</mean>
              <stddev>0.0002</stddev>
            </noise>
          </x>
          <y>
            <noise type="gaussian">
              <mean>0.0</mean>
              <stddev>0.0002</stddev>
            </noise>
          </y>
          <z>
            <noise type="gaussian">
              <mean>0.0</mean>
              <stddev>0.0002</stddev>
            </noise>
          </z>
        </angular_velocity>
        <linear_acceleration>
          <x>
            <noise type="gaussian">
              <mean>0.0</mean>
              <stddev>0.017</stddev>
            </noise>
          </x>
          <y>
            <noise type="gaussian">
              <mean>0.0</mean>
              <stddev>0.017</stddev>
            </noise>
          </y>
          <z>
            <noise type="gaussian">
              <mean>0.0</mean>
              <stddev>0.017</stddev>
            </noise>
          </z>
        </linear_acceleration>
      </imu>
    </sensor>
  </gazebo>
  <gazebo reference="camera_link">
    <sensor name="oak_d_lite_camera" type="camera">
      <always_on>true</always_on>
      <update_rate>30.0</update_rate>
      <visualize>false</visualize>
      <camera name="oak_d_lite">
        <horizontal_fov>1.2043</horizontal_fov>
        <image>
          <width>640</width>
          <height>480</height>
          <format>B8G8R8</format>
        </image>
        <clip>
          <near>0.2</near>
          <far>19.1</far>
        </clip>
        <noise>
          <type>gaussian</type>
          <mean>0.0</mean>
          <stddev>0.005</stddev>
        </noise>
      </camera>
      <plugin filename="libgazebo_ros_camera.so" name="gazebo_ros_camera">
        <ros>
          <remapping>~/image_raw:=camera/image_raw</remapping>
          <remapping>~/camera_info:=camera/camera_info</remapping>
        </ros>
        <frame_name>camera_link_optical</frame_name>
      </plugin>
    </sensor>
  </gazebo>
  <gazebo reference="camera_link">
    <sensor name="oak_d_lite_depth" type="depth">
      <always_on>true</always_on>
      <update_rate>30.0</update_rate>
      <visualize>false</visualize>
      <camera name="oak_d_lite_depth">
        <horizontal_fov>1.2043</horizontal_fov>
        <image>
          <width>640</width>
          <height>480</height>
          <format>B8G8R8</format>
        </image>
        <clip>
          <near>0.1</near>
          <far>100.0</far>
        </clip>
        <noise>
          <type>gaussian</type>
          <mean>0.0</mean>
          <stddev>0.005</stddev>
        </noise>
      </camera>
      <plugin filename="libgazebo_ros_camera.so" name="gazebo_ros_depth_camera">
        <ros>
          <remapping>~/image_raw:=camera/depth/image_raw</remapping>
          <remapping>~/camera_info:=camera/depth/camera_info</remapping>
          <remapping>~/points:=camera/depth/points</remapping>
        </ros>
        <frame_name>camera_link_optical</frame_name>
        <min_depth>0.1</min_depth>
        <max_depth>100.0</max_depth>
      </plugin>
    </sensor>
  </gazebo>
</robot>
